Workbook

Sheet 00_Tong_quan
A1: SPA NHƯ NGUYỆT | TỔNG HỢP PHÂN TÍCH NGHIỆP VỤ & THIẾT KẾ HỆ THỐNG
A2: Nguồn chính: 126_DA_NTTT_NguyenXuanHoang_2214_v1.docx (báo cáo ĐATN – Chương 2) · tiến độ: đề cương 126_DC · v2.0 · 25/10/2026
A3: Cột 'Nguồn' phân biệt: DA = lấy từ báo cáo; ĐX = đề xuất bổ sung (cần GVHD/chủ spa chốt). Đặc tả UC giữ nguyên nội dung DA; phần bổ sung tách riêng. UC/bảng CSDL bám DA; màn hình, API là thiết kế triển khai đề xuất — repo SpaSystem hiện mới có foundation.
A4: Hạng mục | B4: Giá trị | C4: Ghi chú
A5: Tên đề tài | B5: Xây dựng hệ thống web quản lý các gói dịch vụ chăm sóc da mặt tại spa Như Nguyệt
A6: Sinh viên | B6: Nguyễn Xuân Hoàng — MSSV 22115053122214 — Lớp 22T2
A7: Người hướng dẫn | B7: ThS. Nguyễn Thị Thùy Trang | C7: Bộ môn duyệt: Nguyễn Thị Hà Quyên
A8: Thời gian thực hiện | B8: 31/08/2026 → 20/12/2026 (theo đề cương) | C8: 25_Ke_hoach
A9: Công nghệ | B9: ReactJS + TypeScript (web, responsive) · React Native (Android) · ASP.NET Core Web API (C#, Clean Architecture) · PostgreSQL + EF Core (Npgsql) · JWT · RESTful API | C9: DA – Phương pháp nghiên cứu
A10: Kiến trúc | B10: Client – Server; web và mobile dùng chung RESTful API | C10: DA – Mở đầu
A11: Bảo mật | B11: JWT xác thực/phân quyền; băm mật khẩu bằng ASP.NET Core Identity; CORS; HTTPS; upload ảnh qua API | C11: DA – Mở đầu
A12: Chống trùng lịch | B12: Giao dịch + ràng buộc ở tầng CSDL để hai yêu cầu đồng thời không chiếm cùng khung giờ của cùng nhân viên | C12: DA – Mở đầu; chi tiết 09_Thuat_toan_lich
A13: Phạm vi AI | B13: Hỗ trợ cung cấp thông tin và tư vấn dịch vụ — không chẩn đoán hay kết luận y khoa | C13: DA – Mục tiêu
A15: THỐNG KÊ
A16: Nghiệp vụ lớn | B16: =COUNTA('02_Nghiep_vu'!A5:A100)
A17: Tác nhân | B17: =COUNTA('03_Actor'!A5:A100) | C17: 4 actor người dùng + 4 hệ thống ngoài/nền
A18: Use case | B18: =COUNTA('04_Checklist_UC'!B5:B200) | C18: Theo danh sách actor của DA, gộp UC dùng chung
A19: UC có đặc tả trong DA | B19: =COUNTIF('04_Checklist_UC'!H5:H200,"DA: có đặc tả") | C19: Còn lại: đặc tả đề xuất
A20: Business rules | B20: =COUNTA('06_Business_Rules'!A5:A200)
A21: Màn hình (web + Android) | B21: =COUNTA('11_Man_hinh'!A5:A200) | C21: Tách web/Android ở 01_Dashboard
A22: API endpoints | B22: =COUNTA('12_API_Endpoints'!A5:A400) | C22: SPA-API-001 → 116
A23: Bảng CSDL theo DA | B23: =COUNTIF('17_DB_Bang'!D5:D200,"DA") | C23: + 3 bảng đề xuất bổ sung (ĐX)
A24: Vấn đề rà soát trong DA | B24: =COUNTA('26_Ra_soat_DA'!A5:A200) | C24: Cần sửa trước khi nộp báo cáo
A25: Test case UAT | B25: =COUNTA('23_UAT'!A5:A200)
A27: DANH MỤC SHEET
A28: 01_Dashboard | B28: Tiến độ & phân bổ UC theo nghiệp vụ, sprint, trạng thái (công thức tự cập nhật)
A29: 02_Nghiep_vu | B29: Nghiệp vụ lớn, số UC/API
A30: 03_Actor | B30: Tác nhân theo DA + hệ thống ngoài
A31: 04_Checklist_UC | B31: 34 UC: ưu tiên, độ khó, sprint, trạng thái BE/FE/Mobile/QA, tiêu chí nghiệm thu
A32: 05_Dac_ta_UC | B32: Đặc tả UC trích từ DA (Input, Output, Basic/Alternative/Exception flow) + cột rà soát/bổ sung
A33: 06_Business_Rules | B33: Quy tắc nghiệp vụ, nơi enforce, nguồn
A34: 07_Workflow | B34: Máy trạng thái: LichHen, DonHang, ThanhToan, quyền sử dụng, gói, liệu trình…
A35: 08_Quy_trinh | B35: Luồng nghiệp vụ xuyên suốt và đường đi màn hình
A36: 09_Thuat_toan_lich | B36: Thuật toán giờ trống & chống trùng lịch trên bảng LichLamViec/LichHen
A37: 10_Sidebar | B37: Menu theo vai trò
A38: 11_Man_hinh | B38: Màn hình web + Android, route khớp repo
A39: 12_API_Endpoints | B39: API REST đề xuất
... A54: 27_Truy_vet_MT | B54: Mục tiêu đề tài → UC
A56: ĐIỂM CẦN CHỐT
A57: Trợ lý AI cho khách vãng lai | B57: DA cho phép nhưng LichSuTroChuyenAI.IdKhachHang not null (RS-11)
...

Sheet 01_Dashboard
B2: DASHBOARD TIẾN ĐỘ & PHÂN RÃ NGHIỆP VỤ — SPA NHƯ NGUYỆT
B3: Tự cập nhật từ các sheet · nguồn 126_DA_NTTT_NguyenXuanHoang_2214_v1.docx · v2.0 · 25/10/2026
B5: TỔNG USE CASE | C5: UC P0 | D5: API | E5: MÀN HÌNH | F5: BẢNG DA | G5: VẤN ĐỀ DA | H5: TB TIẾN ĐỘ
B6: =COUNTA('04_Checklist_UC'!B5:B200) | C6: =COUNTIF('04_Checklist_UC'!I5:I200,"P0") | D6: =COUNTA('12_API_Endpoints'!A5:A400) | E6: =COUNTA('11_Man_hinh'!A5:A200) | F6: =COUNTIF('17_DB_Bang'!D5:D200,"DA") | G6: =COUNTIF('26_Ra_soat_DA'!G5:G200,"Chưa") | H6: =IFERROR(AVERAGE('04_Checklist_UC'!Q5:Q200),0)
B8: 1. PHÂN BỔ THEO NGHIỆP VỤ LỚN
B9: Mã | C9: Nghiệp vụ lớn | D9: Số UC | E9: Tỷ lệ | F9: UC P0 | G9: Số API | H9: TB tiến độ | I9: Trạng thái
B10: AUTH | C10: Tài khoản & xác thực | D10: =COUNTIF('04_Checklist_UC'!D$5:D$200,B10) | E10: =IFERROR(D10/$D$22,0) | F10: =COUNTIFS('04_Checklist_UC'!D$5:D$200,B10,'04_Checklist_UC'!I$5:I$200,"P0") | G10: =COUNTIF('12_API_Endpoints'!B$5:B$400,B10) | H10: =IFERROR(AVERAGEIF('04_Checklist_UC'!D$5:D$200,B10,'04_Checklist_UC'!Q$5:Q$200),0) | I10: =IF(D10=0,"Không có UC",IF(H10=1,"Hoàn thành",IF(H10>0,"Đang triển khai","Chưa bắt đầu")))
B11: CAT | C11: Dịch vụ & gói dịch vụ | D11: =COUNTIF('04_Checklist_UC'!D$5:D$200,B11) | E11: =IFERROR(D11/$D$22,0) | F11: =COUNTIFS('04_Checklist_UC'!D$5:D$200,B11,'04_Checklist_UC'!I$5:I$200,"P0") | G11: =COUNTIF('12_API_Endpoints'!B$5:B$400,B11) | H11: =IFERROR(AVERAGEIF('04_Checklist_UC'!D$5:D$200,B11,'04_Checklist_UC'!Q$5:Q$200),0) | I11: =IF(D11=0,"Không có UC",IF(H11=1,"Hoàn thành",IF(H11>0,"Đang triển khai","Chưa bắt đầu")))
B12: ORD | C12: Giỏ hàng, đơn hàng & thanh toán | D12: =COUNTIF('04_Checklist_UC'!D$5:D$200,B12) | E12: =IFERROR(D12/$D$22,0) | F12: =COUNTIFS('04_Checklist_UC'!D$5:D$200,B12,'04_Checklist_UC'!I$5:I$200,"P0") | G12: =COUNTIF('12_API_Endpoints'!B$5:B$400,B12) | H12: =IFERROR(AVERAGEIF('04_Checklist_UC'!D$5:D$200,B12,'04_Checklist_UC'!Q$5:Q$200),0) | I12: =IF(D12=0,"Không có UC",IF(H12=1,"Hoàn thành",IF(H12>0,"Đang triển khai","Chưa bắt đầu")))
B13: PRM | C13: Khuyến mãi | D13: =COUNTIF('04_Checklist_UC'!D$5:D$200,B13) | E13: =IFERROR(D13/$D$22,0) | F13: =COUNTIFS('04_Checklist_UC'!D$5:D$200,B13,'04_Checklist_UC'!I$5:I$200,"P0") | G13: =COUNTIF('12_API_Endpoints'!B$5:B$400,B13) | H13: =IFERROR(AVERAGEIF('04_Checklist_UC'!D$5:D$200,B13,'04_Checklist_UC'!Q$5:Q$200),0) | I13: =IF(D13=0,"Không có UC",IF(H13=1,"Hoàn thành",IF(H13>0,"Đang triển khai","Chưa bắt đầu")))
B14: BKG | C14: Đặt lịch & lịch hẹn | D14: =COUNTIF('04_Checklist_UC'!D$5:D$200,B14) | E14: =IFERROR(D14/$D$22,0) | F14: =COUNTIFS('04_Checklist_UC'!D$5:D$200,B14,'04_Checklist_UC'!I$5:I$200,"P0") | G14: =COUNTIF('12_API_Endpoints'!B$5:B$400,B14) | H14: =IFERROR(AVERAGEIF('04_Checklist_UC'!D$5:D$200,B14,'04_Checklist_UC'!Q$5:Q$200),0) | I14: =IF(D14=0,"Không có UC",IF(H14=1,"Hoàn thành",IF(H14>0,"Đang triển khai","Chưa bắt đầu")))
B15: TRT | C15: Quyền sử dụng & liệu trình | D15: =COUNTIF('04_Checklist_UC'!D$5:D$200,B15) | E15: =IFERROR(D15/$D$22,0) | F15: =COUNTIFS('04_Checklist_UC'!D$5:D$200,B15,'04_Checklist_UC'!I$5:I$200,"P0") | G15: =COUNTIF('12_API_Endpoints'!B$5:B$400,B15) | H15: =IFERROR(AVERAGEIF('04_Checklist_UC'!D$5:D$200,B15,'04_Checklist_UC'!Q$5:Q$200),0) | I15: =IF(D15=0,"Không có UC",IF(H15=1,"Hoàn thành",IF(H15>0,"Đang triển khai","Chưa bắt đầu")))
B16: STF | C16: Nhân viên & lịch làm việc | D16: =COUNTIF('04_Checklist_UC'!D$5:D$200,B16) | E16: =IFERROR(D16/$D$22,0) | F16: =COUNTIFS('04_Checklist_UC'!D$5:D$200,B16,'04_Checklist_UC'!I$5:I$200,"P0") | G16: =COUNTIF('12_API_Endpoints'!B$5:B$400,B16) | H16: =IFERROR(AVERAGEIF('04_Checklist_UC'!D$5:D$200,B16,'04_Checklist_UC'!Q$5:Q$200),0) | I16: =IF(D16=0,"Không có UC",IF(H16=1,"Hoàn thành",IF(H16>0,"Đang triển khai","Chưa bắt đầu")))
B17: CARE | C17: Chăm sóc & hồ sơ da | D17: =COUNTIF('04_Checklist_UC'!D$5:D$200,B17) | E17: =IFERROR(D17/$D$22,0) | F17: =COUNTIFS('04_Checklist_UC'!D$5:D$200,B17,'04_Checklist_UC'!I$5:I$200,"P0") | G17: =COUNTIF('12_API_Endpoints'!B$5:B$400,B17) | H17: =IFERROR(AVERAGEIF('04_Checklist_UC'!D$5:D$200,B17,'04_Checklist_UC'!Q$5:Q$200),0) | I17: =IF(D17=0,"Không có UC",IF(H17=1,"Hoàn thành",IF(H17>0,"Đang triển khai","Chưa bắt đầu")))
B18: REV | C18: Đánh giá | D18: =COUNTIF('04_Checklist_UC'!D$5:D$200,B18) | E18: =IFERROR(D18/$D$22,0) | F18: =COUNTIFS('04_Checklist_UC'!D$5:D$200,B18,'04_Checklist_UC'!I$5:I$200,"P0") | G18: =COUNTIF('12_API_Endpoints'!B$5:B$400,B18) | H18: =IFERROR(AVERAGEIF('04_Checklist_UC'!D$5:D$200,B18,'04_Checklist_UC'!Q$5:Q$200),0) | I18: =IF(D18=0,"Không có UC",IF(H18=1,"Hoàn thành",IF(H18>0,"Đang triển khai","Chưa bắt đầu")))
B19: AI | C19: Trợ lý AI | D19: =COUNTIF('04_Checklist_UC'!D$5:D$200,B19) | E19: =IFERROR(D19/$D$22,0) | F19: =COUNTIFS('04_Checklist_UC'!D$5:D$200,B19,'04_Checklist_UC'!I$5:I$200,"P0") | G19: =COUNTIF('12_API_Endpoints'!B$5:B$400,B19) | H19: =IFERROR(AVERAGEIF('04_Checklist_UC'!D$5:D$200,B19,'04_Checklist_UC'!Q$5:Q$200),0) | I19: =IF(D19=0,"Không có UC",IF(H19=1,"Hoàn thành",IF(H19>0,"Đang triển khai","Chưa bắt đầu")))
B20: RPT | C20: Thống kê & báo cáo | D20: =COUNTIF('04_Checklist_UC'!D$5:D$200,B20) | E20: =IFERROR(D20/$D$22,0) | F20: =COUNTIFS('04_Checklist_UC'!D$5:D$200,B20,'04_Checklist_UC'!I$5:I$200,"P0") | G20: =COUNTIF('12_API_Endpoints'!B$5:B$400,B20) | H20: =IFERROR(AVERAGEIF('04_Checklist_UC'!D$5:D$200,B20,'04_Checklist_UC'!Q$5:Q$200),0) | I20: =IF(D20=0,"Không có UC",IF(H20=1,"Hoàn thành",IF(H20>0,"Đang triển khai","Chưa bắt đầu")))
B21: NTF | C21: Thông báo | D21: =COUNTIF('04_Checklist_UC'!D$5:D$200,B21) | E21: =IFERROR(D21/$D$22,0) | F21: =COUNTIFS('04_Checklist_UC'!D$5:D$200,B21,'04_Checklist_UC'!I$5:I$200,"P0") | G21: =COUNTIF('12_API_Endpoints'!B$5:B$400,B21) | H21: =IFERROR(AVERAGEIF('04_Checklist_UC'!D$5:D$200,B21,'04_Checklist_UC'!Q$5:Q$200),0) | I21: =IF(D21=0,"Không có UC",IF(H21=1,"Hoàn thành",IF(H21>0,"Đang triển khai","Chưa bắt đầu")))
B22: TỔNG | C22: (chưa gồm 3 API hệ thống /system, /health) | D22: =SUM(D10:D21) | E22: =IFERROR(D22/D22,0) | F22: =SUM(F10:F21) | G22: =SUM(G10:G21) | H22: =IFERROR(AVERAGE('04_Checklist_UC'!Q5:Q200),0)
B24: 2. PHÂN BỔ THEO SPRINT
B25: Sprint | C25: Chủ đề | D25: Số UC | E25: UC P0 | F25: Tổng độ khó | G25: TB tiến độ | H25: Thời gian
B26: Sprint 1 | C26: Tài khoản, danh mục, nhân viên, đặt lịch lõi | D26: =COUNTIF('04_Checklist_UC'!K$5:K$200,B26) | E26: =COUNTIFS('04_Checklist_UC'!K$5:K$200,B26,'04_Checklist_UC'!I$5:I$200,"P0") | F26: =SUMIF('04_Checklist_UC'!K$5:K$200,B26,'04_Checklist_UC'!J$5:J$200) | G26: =IFERROR(AVERAGEIF('04_Checklist_UC'!K$5:K$200,B26,'04_Checklist_UC'!Q$5:Q$200),0) | H26: 12/10 → 08/11/2026
B27: Sprint 2 | C27: Mua hàng, quyền sử dụng, liệu trình, chăm sóc | D27: =COUNTIF('04_Checklist_UC'!K$5:K$200,B27) | E27: =COUNTIFS('04_Checklist_UC'!K$5:K$200,B27,'04_Checklist_UC'!I$5:I$200,"P0") | F27: =SUMIF('04_Checklist_UC'!K$5:K$200,B27,'04_Checklist_UC'!J$5:J$200) | G27: =IFERROR(AVERAGEIF('04_Checklist_UC'!K$5:K$200,B27,'04_Checklist_UC'!Q$5:Q$200),0) | H27: 26/10 → 22/11/2026
B28: Sprint 3 | C28: AI, báo cáo, thông báo | D28: =COUNTIF('04_Checklist_UC'!K$5:K$200,B28) | E28: =COUNTIFS('04_Checklist_UC'!K$5:K$200,B28,'04_Checklist_UC'!I$5:I$200,"P0") | F28: =SUMIF('04_Checklist_UC'!K$5:K$200,B28,'04_Checklist_UC'!J$5:J$200) | G28: =IFERROR(AVERAGEIF('04_Checklist_UC'!K$5:K$200,B28,'04_Checklist_UC'!Q$5:Q$200),0) | H28: 09/11 → 06/12/2026
B30: 3. TRẠNG THÁI TRIỂN KHAI
B31: Trạng thái | C31: BE | D31: FE Web | E31: Mobile | F31: QA
B32: Chưa làm | C32: =COUNTIF('04_Checklist_UC'!M$5:M$200,B32) | D32: =COUNTIF('04_Checklist_UC'!N$5:N$200,B32) | E32: =COUNTIF('04_Checklist_UC'!O$5:O$200,B32) | F32: =COUNTIF('04_Checklist_UC'!P$5:P$200,B32)
B33: Đang làm | C33: =COUNTIF('04_Checklist_UC'!M$5:M$200,B33) | D33: =COUNTIF('04_Checklist_UC'!N$5:N$200,B33) | E33: =COUNTIF('04_Checklist_UC'!O$5:O$200,B33) | F33: =COUNTIF('04_Checklist_UC'!P$5:P$200,B33)
B34: Done chờ Test | C34: =COUNTIF('04_Checklist_UC'!M$5:M$200,B34) | D34: =COUNTIF('04_Checklist_UC'!N$5:N$200,B34) | E34: =COUNTIF('04_Checklist_UC'!O$5:O$200,B34) | F34: =COUNTIF('04_Checklist_UC'!P$5:P$200,B34)
B35: Hoàn thành | C35: =COUNTIF('04_Checklist_UC'!M$5:M$200,B35) | D35: =COUNTIF('04_Checklist_UC'!N$5:N$200,B35) | E35: =COUNTIF('04_Checklist_UC'!O$5:O$200,B35) | F35: =COUNTIF('04_Checklist_UC'!P$5:P$200,B35)
B36: Tạm dừng | C36: =COUNTIF('04_Checklist_UC'!M$5:M$200,B36) | D36: =COUNTIF('04_Checklist_UC'!N$5:N$200,B36) | E36: =COUNTIF('04_Checklist_UC'!O$5:O$200,B36) | F36: =COUNTIF('04_Checklist_UC'!P$5:P$200,B36)
B37: N/A | C37: =COUNTIF('04_Checklist_UC'!M$5:M$200,B37) | D37: =COUNTIF('04_Checklist_UC'!N$5:N$200,B37) | E37: =COUNTIF('04_Checklist_UC'!O$5:O$200,B37) | F37: =COUNTIF('04_Checklist_UC'!P$5:P$200,B37)
B39: 4. MÀN HÌNH, API, TÀI LIỆU
B40: Chỉ tiêu | C40: Giá trị
B41: Màn hình Web | C41: =COUNTIF('11_Man_hinh'!B5:B200,"Web")
B42: Màn hình Android | C42: =COUNTIF('11_Man_hinh'!B5:B200,"Android")
B43: Route đã có placeholder | C43: =COUNTIF('11_Man_hinh'!G5:G200,"Đã có placeholder")
B44: Route cần tạo / đổi tên | C44: =COUNTA('11_Man_hinh'!G5:G200)-COUNTIF('11_Man_hinh'!G5:G200,"Đã có placeholder")
B45: API GET | C45: =COUNTIF('12_API_Endpoints'!E5:E400,"GET")
B46: API ghi (POST/PUT/PATCH/DELETE) | C46: =COUNTA('12_API_Endpoints'!E5:E400)-COUNTIF('12_API_Endpoints'!E5:E400,"GET")
...

Sheet 02_Nghiep_vu
A1: 02 · DANH SÁCH NGHIỆP VỤ LỚN
A2: 12 nghiệp vụ · gom từ danh sách UC của DA
A3: Số UC / P0 / API là công thức đếm từ 04_Checklist_UC và 12_API_Endpoints.
A4: Mã nhóm | B4: Nghiệp vụ lớn | C4: Mô tả phạm vi | D4: Nguồn | E4: Số UC | F4: UC P0 | G4: Số API | H4: Danh sách UC
A5: AUTH | B5: Tài khoản & xác thực | C5: Đăng ký (OTP email), đăng nhập theo vai trò, quên mật khẩu (OTP), cập nhật thông tin, chủ spa quản lý tài khoản | D5: DA §2.2.1 | E5: =COUNTIF('04_Checklist_UC'!D$5:D$200,A5) | F5: =COUNTIFS('04_Checklist_UC'!D$5:D$200,A5,'04_Checklist_UC'!I$5:I$200,"P0") | G5: =COUNTIF('12_API_Endpoints'!B$5:B$400,A5) | H5: UC-SPA-01, UC-SPA-02, UC-SPA-03, UC-SPA-04, UC-SPA-05
A6: CAT | B6: Dịch vụ & gói dịch vụ | C6: Tìm kiếm, xem chi tiết, giới thiệu spa; chủ spa quản lý dịch vụ và gói (dịch vụ thành phần, số buổi) | D6: DA §2.2.1 | E6: =COUNTIF('04_Checklist_UC'!D$5:D$200,A6) | F6: =COUNTIFS('04_Checklist_UC'!D$5:D$200,A6,'04_Checklist_UC'!I$5:I$200,"P0") | G6: =COUNTIF('12_API_Endpoints'!B$5:B$400,A6) | H6: UC-SPA-06, UC-SPA-07, UC-SPA-08, UC-SPA-09
A7: ORD | B7: Giỏ hàng, đơn hàng & thanh toán | C7: Giỏ hàng, thanh toán trực tuyến qua cổng, đơn hàng của khách và quản lý đơn của chủ spa | D7: DA §2.2.1 | E7: =COUNTIF('04_Checklist_UC'!D$5:D$200,A7) | F7: =COUNTIFS('04_Checklist_UC'!D$5:D$200,A7,'04_Checklist_UC'!I$5:I$200,"P0") | G7: =COUNTIF('12_API_Endpoints'!B$5:B$400,A7) | H7: UC-SPA-10, UC-SPA-11, UC-SPA-12, UC-SPA-13
A8: PRM | B8: Khuyến mãi | C8: Chủ spa quản lý chương trình; khách nhập mã khi thanh toán | D8: DA §2.2.1 | E8: =COUNTIF('04_Checklist_UC'!D$5:D$200,A8) | F8: =COUNTIFS('04_Checklist_UC'!D$5:D$200,A8,'04_Checklist_UC'!I$5:I$200,"P0") | G8: =COUNTIF('12_API_Endpoints'!B$5:B$400,A8) | H8: UC-SPA-14
A9: BKG | B9: Đặt lịch & lịch hẹn | C9: Đặt lịch (đặt ngay + thanh toán / đặt từ dịch vụ, gói đã mua), đổi/hủy, chủ spa điều phối | D9: DA §2.2.1 | E9: =COUNTIF('04_Checklist_UC'!D$5:D$200,A9) | F9: =COUNTIFS('04_Checklist_UC'!D$5:D$200,A9,'04_Checklist_UC'!I$5:I$200,"P0") | G9: =COUNTIF('12_API_Endpoints'!B$5:B$400,A9) | H9: UC-SPA-15, UC-SPA-16, UC-SPA-17
A10: TRT | B10: Quyền sử dụng & liệu trình | C10: Dịch vụ và gói đã mua, liệu trình nhiều buổi, lịch sử sử dụng | D10: DA §2.2.1 | E10: =COUNTIF('04_Checklist_UC'!D$5:D$200,A10) | F10: =COUNTIFS('04_Checklist_UC'!D$5:D$200,A10,'04_Checklist_UC'!I$5:I$200,"P0") | G10: =COUNTIF('12_API_Endpoints'!B$5:B$400,A10) | H10: UC-SPA-18, UC-SPA-19, UC-SPA-20, UC-SPA-21
A11: STF | B11: Nhân viên & lịch làm việc | C11: Hồ sơ nhân viên, nghỉ việc, phân công ca, nhân viên xem lịch và lịch hẹn được phân công | D11: DA §2.2.1 | E11: =COUNTIF('04_Checklist_UC'!D$5:D$200,A11) | F11: =COUNTIFS('04_Checklist_UC'!D$5:D$200,A11,'04_Checklist_UC'!I$5:I$200,"P0") | G11: =COUNTIF('12_API_Endpoints'!B$5:B$400,A11) | H11: UC-SPA-22, UC-SPA-23, UC-SPA-24, UC-SPA-25
A12: CARE | B12: Chăm sóc & hồ sơ da | C12: Lịch sử khách đã chăm sóc, hồ sơ da, dị ứng, xác nhận hoàn thành buổi | D12: DA §2.2.1 | E12: =COUNTIF('04_Checklist_UC'!D$5:D$200,A12) | F12: =COUNTIFS('04_Checklist_UC'!D$5:D$200,A12,'04_Checklist_UC'!I$5:I$200,"P0") | G12: =COUNTIF('12_API_Endpoints'!B$5:B$400,A12) | H12: UC-SPA-26, UC-SPA-27, UC-SPA-28
A13: REV | B13: Đánh giá | C13: Xem đánh giá, khách đánh giá (kèm ảnh), chủ spa phản hồi/ẩn | D13: DA §2.2.1 | E13: =COUNTIF('04_Checklist_UC'!D$5:D$200,A13) | F13: =COUNTIFS('04_Checklist_UC'!D$5:D$200,A13,'04_Checklist_UC'!I$5:I$200,"P0") | G13: =COUNTIF('12_API_Endpoints'!B$5:B$400,A13) | H13: UC-SPA-29, UC-SPA-30, UC-SPA-31
A14: AI | B14: Trợ lý AI | C14: Tư vấn dịch vụ theo nhu cầu, lưu lịch sử trao đổi | D14: DA §2.2.1 | E14: =COUNTIF('04_Checklist_UC'!D$5:D$200,A14) | F14: =COUNTIFS('04_Checklist_UC'!D$5:D$200,A14,'04_Checklist_UC'!I$5:I$200,"P0") | G14: =COUNTIF('12_API_Endpoints'!B$5:B$400,A14) | H14: UC-SPA-32
A15: RPT | B15: Thống kê & báo cáo | C15: Doanh thu theo khoảng thời gian và tiêu chí, biểu đồ | D15: DA §2.2.1 | E15: =COUNTIF('04_Checklist_UC'!D$5:D$200,A15) | F15: =COUNTIFS('04_Checklist_UC'!D$5:D$200,A15,'04_Checklist_UC'!I$5:I$200,"P0") | G15: =COUNTIF('12_API_Endpoints'!B$5:B$400,A15) | H15: UC-SPA-33
A16: NTF | B16: Thông báo | C16: Thông báo/nhắc lịch cho khách hàng và nhân viên | D16: DA §2.2.1 | E16: =COUNTIF('04_Checklist_UC'!D$5:D$200,A16) | F16: =COUNTIFS('04_Checklist_UC'!D$5:D$200,A16,'04_Checklist_UC'!I$5:I$200,"P0") | G16: =COUNTIF('12_API_Endpoints'!B$5:B$400,A16) | H16: UC-SPA-34

Sheet 03_Actor
A1: 03 · TÁC NHÂN (ACTOR)
A2: Theo mục 'Liệt kê Actor và Usecase' của DA + hệ thống ngoài
A3: Mã actor dùng trong cột Actor / Vai trò ở các sheet khác.
A4: Mã | B4: Tác nhân | C4: Phạm vi | D4: Nền tảng | E4: Nguồn | F4: Số UC tham gia
A5: GUEST | B5: Khách vãng lai | C5: Tìm kiếm, xem chi tiết dịch vụ/gói, xem giới thiệu spa, xem đánh giá, đăng ký, đăng nhập, quên mật khẩu; theo đặc tả còn được trò chuyện với AI | D5: Web, Android | E5: DA – Liệt kê Actor | F5: =COUNTIF('04_Checklist_UC'!G$5:G$200,"*"&A5&"*")
A6: CUS | B6: Khách hàng | C6: Cập nhật tài khoản, tìm kiếm, AI, dịch vụ/gói đã mua, đặt lịch, giỏ hàng, lịch hẹn, thanh toán, liệu trình, lịch sử, thông báo, đơn hàng, đánh giá | D6: Web, Android | E6: DA – Liệt kê Actor | F6: =COUNTIF('04_Checklist_UC'!G$5:G$200,"*"&A6&"*")
A7: STF | B7: Nhân viên | C7: Cập nhật tài khoản, thông báo, lịch làm việc cá nhân, lịch hẹn được phân công, lịch sử khách đã chăm sóc, hồ sơ da, xác nhận hoàn thành, quản lý liệu trình | D7: Web, Android | E7: DA – Liệt kê Actor | F7: =COUNTIF('04_Checklist_UC'!G$5:G$200,"*"&A7&"*")
A8: OWN | B8: Chủ spa | C8: Quản lý nhân viên, tài khoản người dùng, đơn hàng, phân công lịch, dịch vụ & gói, khuyến mãi, lịch hẹn, liệu trình, đánh giá; xem báo cáo doanh thu | D8: Web (Android rút gọn) | E8: DA – Liệt kê Actor | F8: =COUNTIF('04_Checklist_UC'!G$5:G$200,"*"&A8&"*")
A9: PGW | B9: Cổng thanh toán | C9: Xử lý giao dịch và gửi kết quả (DA không nêu tên cổng; ThanhToan.NhaCungCap) | D9: Bên ngoài | E9: DA – UC Thanh toán trực tuyến | F9: =COUNTIF('04_Checklist_UC'!G$5:G$200,"*"&A9&"*")
A10: LLM | B10: Dịch vụ AI | C10: Xử lý câu hỏi và trả kết quả cho trợ lý | D10: Bên ngoài | E10: DA – UC Trò chuyện với AI | F10: =COUNTIF('04_Checklist_UC'!G$5:G$200,"*"&A10&"*")
A11: MAIL | B11: Dịch vụ email | C11: Gửi OTP đăng ký/quên mật khẩu, thông báo nhắc lịch | D11: Bên ngoài | E11: DA – UC Đăng ký, Quên mật khẩu; Mở đầu | F11: =COUNTIF('04_Checklist_UC'!G$5:G$200,"*"&A11&"*")
A12: SYS | B12: Hệ thống (tác vụ nền) | C12: Hết hạn giữ chỗ/đơn, hết hạn quyền sử dụng, gửi nhắc lịch | D12: Backend | E12: ĐX (suy ra từ DonHang.HetHanThanhToanLuc, LichHen.GiuChoDen) | F12: =COUNTIF('04_Checklist_UC'!G$5:G$200,"*"&A12&"*")

Sheet 04_Checklist_UC
A1: 04 · CHECKLIST USE CASE
A2: 34 UC · UC-SPA-01 → UC-SPA-34 · tên UC theo DA · trạng thái tại 25/10/2026: chưa triển khai (repo mới có foundation)
A3: Chỉnh cột M–P. N/A = UC không có trên nền tảng đó. Tiến độ (Q) = trung bình các cột áp dụng: Đang làm 50%, Done chờ Test/Hoàn thành 100%. Ưu tiên, độ khó, sprint, tiêu chí nghiệm thu là ĐỀ XUẤT.
A4: STT | B4: Mã UC | C4: Nghiệp vụ lớn | D4: Mã nhóm | E4: Tên Use Case (DA) | F4: Mô tả (DA) | G4: Actor | H4: Nguồn | I4: Ưu tiên | J4: Độ khó (1-10) | K4: Sprint | L4: Nền tảng | M4: Trạng thái BE | N4: Trạng thái FE Web | O4: Trạng thái Mobile | P4: Trạng thái QA | Q4: Tiến độ | R4: Tiêu chí nghiệm thu (ĐX) | S4: Ghi chú
A5: 1 | B5: UC-SPA-01 | C5: Tài khoản & xác thực | D5: AUTH | E5: Đăng ký tài khoản | F5: Khách tạo tài khoản thông qua xác thực OTP email | G5: GUEST | H5: DA: có đặc tả | I5: P0 | J5: 4 | K5: Sprint 1 | L5: Web, Android | M5: Chưa làm | N5: Chưa làm | O5: Chưa làm | P5: Chưa làm | Q5: =IFERROR(ROUND((IF(M5="Hoàn thành",1,IF(M5="Done chờ Test",1,IF(M5="Đang làm",0.5,0)))+IF(N5="Hoàn thành",1,IF(N5="Done chờ Test",1,IF(N5="Đang làm",0.5,0)))+IF(O5="Hoàn thành",1,IF(O5="Done chờ Test",1,IF(O5="Đang làm",0.5,0)))+IF(P5="Hoàn thành",1,IF(P5="Done chờ Test",1,IF(P5="Đang làm",0.5,0))))/(4-COUNTIF(M5:P5,"N/A")),4),0) | R5: Email, SĐT duy nhất; OTP 6 số hết hạn sau 5 phút, tối đa 5 lần nhập sai; chỉ tạo NguoiDung + KhachHang sau khi OTP đúng; chuyển đến đăng nhập | S5: Cần lưu tạm thông tin đăng ký + OTP (ERD chưa có bảng)
A6: 2 | B6: UC-SPA-02 | C6: Tài khoản & xác thực | D6: AUTH | E6: Đăng nhập | F6: Người dùng đăng nhập để sử dụng chức năng theo vai trò | G6: CUS; STF; OWN | H6: DA: có đặc tả | I6: P0 | J6: 4 | K6: Sprint 1 | L6: Web, Android | M6: Chưa làm | N6: Chưa làm | O6: Chưa làm | P6: Chưa làm | Q6: =IFERROR(ROUND((IF(M6="Hoàn thành",1,IF(M6="Done chờ Test",1,IF(M6="Đang làm",0.5,0)))+IF(N6="Hoàn thành",1,IF(N6="Done chờ Test",1,IF(N6="Đang làm",0.5,0)))+IF(O6="Hoàn thành",1,IF(O6="Done chờ Test",1,IF(O6="Đang làm",0.5,0)))+IF(P6="Hoàn thành",1,IF(P6="Done chờ Test",1,IF(P6="Đang làm",0.5,0))))/(4-COUNTIF(M6:P6,"N/A")),4),0) | R6: Đăng nhập bằng email/SĐT + mật khẩu; tài khoản bị khóa/ngừng hoạt động bị từ chối; điều hướng theo VaiTro; A1 quay lại thao tác đang dở | S6: JWT
A7: 3 | B7: UC-SPA-03 | C7: Tài khoản & xác thực | D7: AUTH | E7: Quên mật khẩu | F7: Người dùng đặt lại mật khẩu bằng OTP gửi qua email | G7: CUS; STF; OWN | H7: DA: có đặc tả | I7: P1 | J7: 4 | K7: Sprint 1 | L7: Web, Android | M7: Chưa làm | N7: Chưa làm | O7: Chưa làm | P7: Chưa làm | Q7: =IFERROR(ROUND((IF(M7="Hoàn thành",1,IF(M7="Done chờ Test",1,IF(M7="Đang làm",0.5,0)))+IF(N7="Hoàn thành",1,IF(N7="Done chờ Test",1,IF(N7="Đang làm",0.5,0)))+IF(O7="Hoàn thành",1,IF(O7="Done chờ Test",1,IF(O7="Đang làm",0.5,0)))+IF(P7="Hoàn thành",1,IF(P7="Done chờ Test",1,IF(P7="Đang làm",0.5,0))))/(4-COUNTIF(M7:P7,"N/A")),4),0) | R7: OTP dùng 1 lần, hết hạn 5 phút; mật khẩu mới đủ mạnh và khớp xác nhận; đặt lại xong thu hồi các phiên đăng nhập | S7: DA ghi chú: sơ đồ chưa có nhánh mật khẩu mới không hợp lệ
A8: 4 | B8: UC-SPA-04 | C8: Tài khoản & xác thực | D8: AUTH | E8: Cập nhật thông tin tài khoản | F8: Người dùng chỉnh sửa thông tin cá nhân | G8: CUS; STF; OWN | H8: DA: có đặc tả | I8: P1 | J8: 2 | K8: Sprint 1 | L8: Web, Android | M8: Chưa làm | N8: Chưa làm | O8: Chưa làm | P8: Chưa làm | Q8: =IFERROR(ROUND((IF(M8="Hoàn thành",1,IF(M8="Done chờ Test",1,IF(M8="Đang làm",0.5,0)))+IF(N8="Hoàn thành",1,IF(N8="Done chờ Test",1,IF(N8="Đang làm",0.5,0)))+IF(O8="Hoàn thành",1,IF(O8="Done chờ Test",1,IF(O8="Đang làm",0.5,0)))+IF(P8="Hoàn thành",1,IF(P8="Done chờ Test",1,IF(P8="Đang làm",0.5,0))))/(4-COUNTIF(M8:P8,"N/A")),4),0) | R8: Sửa HoTen, SDT, NgaySinh, GioiTinh, AnhDaiDien; không tự đổi VaiTro/TrangThai; SĐT không trùng
A9: 5 | B9: UC-SPA-05 | C9: Tài khoản & xác thực | D9: AUTH | E9: Quản lý tài khoản người dùng | F9: Chủ spa xem hoặc chỉnh sửa và khóa hoặc mở tài khoản | G9: OWN | H9: DA: có đặc tả | I9: P1 | J9: 3 | K9: Sprint 2 | L9: Web | M9: Chưa làm | N9: Chưa làm | O9: N/A | P9: Chưa làm | Q9: =IFERROR(ROUND((IF(M9="Hoàn thành",1,IF(M9="Done chờ Test",1,IF(M9="Đang làm",0.5,0)))+IF(N9="Hoàn thành",1,IF(N9="Done chờ Test",1,IF(N9="Đang làm",0.5,0)))+IF(O9="Hoàn thành",1,IF(O9="Done chờ Test",1,IF(O9="Đang làm",0.5,0)))+IF(P9="Hoàn thành",1,IF(P9="Done chờ Test",1,IF(P9="Đang làm",0.5,0))))/(4-COUNTIF(M9:P9,"N/A")),4),0) | R9: Tìm theo tên/email/SĐT/vai trò; khóa tài khoản thì thu hồi phiên đăng nhập; chủ spa không tự khóa chính mình
A10: 6 | B10: UC-SPA-06 | C10: Dịch vụ & gói dịch vụ | D10: CAT | E10: Tìm kiếm dịch vụ và gói dịch vụ | F10: Khách vãng lai hoặc khách hàng tìm kiếm các dịch vụ, gói dịch vụ chăm sóc da đang có trên hệ thống | G10: GUEST; CUS | H10: DA: có đặc tả | I10: P0 | J10: 4 | K10: Sprint 1 | L10: Web, Android | M10: Chưa làm | N10: Chưa làm | O10: Chưa làm | P10: Chưa làm | Q10: =IFERROR(ROUND((IF(M10="Hoàn thành",1,IF(M10="Done chờ Test",1,IF(M10="Đang làm",0.5,0)))+IF(N10="Hoàn thành",1,IF(N10="Done chờ Test",1,IF(N10="Đang làm",0.5,0)))+IF(O10="Hoàn thành",1,IF(O10="Done chờ Test",1,IF(O10="Đang làm",0.5,0)))+IF(P10="Hoàn thành",1,IF(P10="Done chờ Test",1,IF(P10="Đang làm",0.5,0))))/(4-COUNTIF(M10:P10,"N/A")),4),0) | R10: Chỉ hiển thị mục TrangThai = DangBan; lọc theo từ khóa, danh mục (LoaiDichVu), khoảng giá; khách đã đăng nhập lọc 'chỉ dịch vụ đã từng sử dụng'; phân trang | S10: A3: hỏi trợ lý AI ngay từ trang tìm kiếm
A11: 7 | B11: UC-SPA-07 | C11: Dịch vụ & gói dịch vụ | D11: CAT | E11: Xem chi tiết dịch vụ, gói dịch vụ | F11: Xem mô tả, thời lượng, giá, hình ảnh; với gói: dịch vụ thành phần, số buổi, thứ tự, thời hạn | G11: GUEST; CUS | H11: DA: chỉ liệt kê, chưa đặc tả | I11: P0 | J11: 2 | K11: Sprint 1 | L11: Web, Android | M11: Chưa làm | N11: Chưa làm | O11: Chưa làm | P11: Chưa làm | Q11: =IFERROR(ROUND((IF(M11="Hoàn thành",1,IF(M11="Done chờ Test",1,IF(M11="Đang làm",0.5,0)))+IF(N11="Hoàn thành",1,IF(N11="Done chờ Test",1,IF(N11="Đang làm",0.5,0)))+IF(O11="Hoàn thành",1,IF(O11="Done chờ Test",1,IF(O11="Đang làm",0.5,0)))+IF(P11="Hoàn thành",1,IF(P11="Done chờ Test",1,IF(P11="Đang làm",0.5,0))))/(4-COUNTIF(M11:P11,"N/A")),4),0) | R11: Gói hiển thị GoiDichVuChiTiet theo ThuTu; có nút Thêm vào giỏ / Đặt ngay (dịch vụ) / Mua gói; mục ngừng bán trả 404 với khách | S11: Có trong danh sách UC của Khách vãng lai nhưng chưa có bảng đặc tả
A12: 8 | B12: UC-SPA-08 | C12: Dịch vụ & gói dịch vụ | D12: CAT | E12: Xem thông tin giới thiệu về spa | F12: Người dùng xem thông tin giới thiệu và liên hệ của spa | G12: GUEST; CUS | H12: DA: có đặc tả | I12: P2 | J12: 1 | K12: Sprint 1 | L12: Web, Android | M12: Chưa làm | N12: Chưa làm | O12: Chưa làm | P12: Chưa làm | Q12: =IFERROR(ROUND((IF(M12="Hoàn thành",1,IF(M12="Done chờ Test",1,IF(M12="Đang làm",0.5,0)))+IF(N12="Hoàn thành",1,IF(N12="Done chờ Test",1,IF(N12="Đang làm",0.5,0)))+IF(O12="Hoàn thành",1,IF(O12="Done chờ Test",1,IF(O12="Đang làm",0.5,0)))+IF(P12="Hoàn thành",1,IF(P12="Done chờ Test",1,IF(P12="Đang làm",0.5,0))))/(4-COUNTIF(M12:P12,"N/A")),4),0) | R12: Hiển thị giới thiệu, địa chỉ, SĐT, giờ mở cửa | S12: Luồng rẽ nhánh/ngoại lệ trong DA đang chép từ UC Tìm kiếm; ERD chưa có bảng thông tin spa
A13: 9 | B13: UC-SPA-09 | C13: Dịch vụ & gói dịch vụ | D13: CAT | E13: Quản lý dịch vụ và gói dịch vụ | F13: Chủ spa thêm hoặc sửa hoặc ngừng bán sản phẩm | G13: OWN | H13: DA: có đặc tả | I13: P0 | J13: 5 | K13: Sprint 1 | L13: Web | M13: Chưa làm | N13: Chưa làm | O13: N/A | P13: Chưa làm | Q13: =IFERROR(ROUND((IF(M13="Hoàn thành",1,IF(M13="Done chờ Test",1,IF(M13="Đang làm",0.5,0)))+IF(N13="Hoàn thành",1,IF(N13="Done chờ Test",1,IF(N13="Đang làm",0.5,0)))+IF(O13="Hoàn thành",1,IF(O13="Done chờ Test",1,IF(O13="Đang làm",0.5,0)))+IF(P13="Hoàn thành",1,IF(P13="Done chờ Test",1,IF(P13="Đang làm",0.5,0))))/(4-COUNTIF(M13:P13,"N/A")),4),0) | R13: Dịch vụ: ThoiLuongPhut > 0, Gia ≥ 0; gói: ≥ 1 dịch vụ thành phần, SoBuoi > 0, ThuTu > 0, KhoangCachNgayToiThieu ≥ 0, ThoiHanNgay > 0; ngừng bán thay vì xóa; sửa không ảnh hưởng đơn/gói đã mua (đã lưu snapshot)
A14: 10 | B14: UC-SPA-10 | C14: Giỏ hàng, đơn hàng & thanh toán | D14: ORD | E14: Quản lý giỏ hàng | F14: Khách thêm hoặc xóa sản phẩm và chuyển sang thanh toán | G14: CUS | H14: DA: có đặc tả | I14: P1 | J14: 3 | K14: Sprint 2 | L14: Web, Android | M14: Chưa làm | N14: Chưa làm | O14: Chưa làm | P14: Chưa làm | Q14: =IFERROR(ROUND((IF(M14="Hoàn thành",1,IF(M14="Done chờ Test",1,IF(M14="Đang làm",0.5,0)))+IF(N14="Hoàn thành",1,IF(N14="Done chờ Test",1,IF(N14="Đang làm",0.5,0)))+IF(O14="Hoàn thành",1,IF(O14="Done chờ Test",1,IF(O14="Đang làm",0.5,0)))+IF(P14="Hoàn thành",1,IF(P14="Done chờ Test",1,IF(P14="Đang làm",0.5,0))))/(4-COUNTIF(M14:P14,"N/A")),4),0) | R14: Mỗi khách 1 giỏ (GioHang.IdKhachHang unique); không thêm trùng sản phẩm; DonGia ghi nhận khi thêm chỉ để tham khảo, giá thật lấy lại khi thanh toán
A15: 11 | B15: UC-SPA-11 | C15: Giỏ hàng, đơn hàng & thanh toán | D15: ORD | E15: Thanh toán trực tuyến | F15: Khách thanh toán đơn qua cổng thanh toán online | G15: CUS; PGW | H15: DA: có đặc tả | I15: P0 | J15: 8 | K15: Sprint 2 | L15: Web, Android | M15: Chưa làm | N15: Chưa làm | O15: Chưa làm | P15: Chưa làm | Q15: =IFERROR(ROUND((IF(M15="Hoàn thành",1,IF(M15="Done chờ Test",1,IF(M15="Đang làm",0.5,0)))+IF(N15="Hoàn thành",1,IF(N15="Done chờ Test",1,IF(N15="Đang làm",0.5,0)))+IF(O15="Hoàn thành",1,IF(O15="Done chờ Test",1,IF(O15="Đang làm",0.5,0)))+IF(P15="Hoàn thành",1,IF(P15="Done chờ Test",1,IF(P15="Đang làm",0.5,0))))/(4-COUNTIF(M15:P15,"N/A")),4),0) | R15: Kiểm tra sản phẩm còn bán và lấy giá hiện tại; áp mã KM (A1); kết quả từ cổng phải được xác thực; thành công → DonHang DaThanhToan và tạo quyền sử dụng (DichVuKhachHang/GoiKhachHang); thất bại cho thử lại trên đơn còn hạn | S15: Cổng thanh toán chưa chốt
A16: 12 | B16: UC-SPA-12 | C16: Giỏ hàng, đơn hàng & thanh toán | D16: ORD | E16: Quản lý đơn hàng đã mua | F16: Khách xem đơn và thực hiện thanh toán lại hoặc hủy đơn chưa thanh toán | G16: CUS | H16: DA: có đặc tả | I16: P1 | J16: 3 | K16: Sprint 2 | L16: Web, Android | M16: Chưa làm | N16: Chưa làm | O16: Chưa làm | P16: Chưa làm | Q16: =IFERROR(ROUND((IF(M16="Hoàn thành",1,IF(M16="Done chờ Test",1,IF(M16="Đang làm",0.5,0)))+IF(N16="Hoàn thành",1,IF(N16="Done chờ Test",1,IF(N16="Đang làm",0.5,0)))+IF(O16="Hoàn thành",1,IF(O16="Done chờ Test",1,IF(O16="Đang làm",0.5,0)))+IF(P16="Hoàn thành",1,IF(P16="Done chờ Test",1,IF(P16="Đang làm",0.5,0))))/(4-COUNTIF(M16:P16,"N/A")),4),0) | R16: Chỉ đơn của chính khách; thanh toán lại khi đơn ChoThanhToan và chưa quá HetHanThanhToanLuc; hủy chỉ khi chưa thanh toán (giải phóng giữ chỗ nếu có)
A17: 13 | B17: UC-SPA-13 | C17: Giỏ hàng, đơn hàng & thanh toán | D17: ORD | E17: Quản lý đơn hàng | F17: Chủ spa xem đơn và hủy đơn chưa thanh toán | G17: OWN | H17: DA: có đặc tả | I17: P1 | J17: 3 | K17: Sprint 2 | L17: Web | M17: Chưa làm | N17: Chưa làm | O17: N/A | P17: Chưa làm | Q17: =IFERROR(ROUND((IF(M17="Hoàn thành",1,IF(M17="Done chờ Test",1,IF(M17="Đang làm",0.5,0)))+IF(N17="Hoàn thành",1,IF(N17="Done chờ Test",1,IF(N17="Đang làm",0.5,0)))+IF(O17="Hoàn thành",1,IF(O17="Done chờ Test",1,IF(O17="Đang làm",0.5,0)))+IF(P17="Hoàn thành",1,IF(P17="Done chờ Test",1,IF(P17="Đang làm",0.5,0))))/(4-COUNTIF(M17:P17,"N/A")),4),0) | R17: Tìm theo mã đơn, khách, trạng thái, khoảng ngày; hủy cần xác nhận và chỉ áp dụng đơn chưa thanh toán
A18: 14 | B18: UC-SPA-14 | C18: Khuyến mãi | D18: PRM | E18: Quản lý chương trình khuyến mãi | F18: Chủ spa thêm hoặc sửa hoặc ngừng khuyến mãi | G18: OWN | H18: DA: có đặc tả | I18: P1 | J18: 4 | K18: Sprint 2 | L18: Web | M18: Chưa làm | N18: Chưa làm | O18: N/A | P18: Chưa làm | Q18: =IFERROR(ROUND((IF(M18="Hoàn thành",1,IF(M18="Done chờ Test",1,IF(M18="Đang làm",0.5,0)))+IF(N18="Hoàn thành",1,IF(N18="Done chờ Test",1,IF(N18="Đang làm",0.5,0)))+IF(O18="Hoàn thành",1,IF(O18="Done chờ Test",1,IF(O18="Đang làm",0.5,0)))+IF(P18="Hoàn thành",1,IF(P18="Done chờ Test",1,IF(P18="Đang làm",0.5,0))))/(4-COUNTIF(M18:P18,"N/A")),4),0) | R18: MaCode duy nhất; GiaTri > 0 và ≤ 100 nếu phần trăm; NgayKetThuc > NgayBatDau; giới hạn mỗi khách và tổng số lượng; ngừng thay vì xóa
A19: 15 | B19: UC-SPA-15 | C19: Đặt lịch & lịch hẹn | D19: BKG | E19: Đặt lịch hẹn | F19: Luồng 1: khách chọn dịch vụ, chọn lịch rồi thanh toán để xác nhận. Luồng 2: đặt lịch từ dịch vụ và gói của tôi | G19: CUS | H19: DA: có đặc tả | I19: P0 | J19: 9 | K19: Sprint 1 | L19: Web, Android | M19: Chưa làm | N19: Chưa làm | O19: Chưa làm | P19: Chưa làm | Q19: =IFERROR(ROUND((IF(M19="Hoàn thành",1,IF(M19="Done chờ Test",1,IF(M19="Đang làm",0.5,0)))+IF(N19="Hoàn thành",1,IF(N19="Done chờ Test",1,IF(N19="Đang làm",0.5,0)))+IF(O19="Hoàn thành",1,IF(O19="Done chờ Test",1,IF(O19="Đang làm",0.5,0)))+IF(P19="Hoàn thành",1,IF(P19="Done chờ Test",1,IF(P19="Đang làm",0.5,0))))/(4-COUNTIF(M19:P19,"N/A")),4),0) | R19: Chỉ hiển thị nhân viên làm được dịch vụ và giờ còn trống trong ca; kiểm tra lại trước khi tạo; luồng 1 giữ chỗ có thời hạn và chỉ xác nhận khi thanh toán thành công trong hạn; luồng 2 kiểm tra hạn dùng, lượt còn lại và khoảng cách tối thiểu giữa các buổi; hai yêu cầu đồng thời không chiếm cùng khung giờ | S19: Lõi của mục tiêu MT-3 — xem 09_Thuat_toan_lich
A20: 16 | B20: UC-SPA-16 | C20: Đặt lịch & lịch hẹn | D20: BKG | E20: Xem và quản lý lịch hẹn | F20: Khách xem hoặc đổi hoặc hủy lịch của mình | G20: CUS | H20: DA: có đặc tả | I20: P1 | J20: 5 | K20: Sprint 2 | L20: Web, Android | M20: Chưa làm | N20: Chưa làm | O20: Chưa làm | P20: Chưa làm | Q20: =IFERROR(ROUND((IF(M20="Hoàn thành",1,IF(M20="Done chờ Test",1,IF(M20="Đang làm",0.5,0)))+IF(N20="Hoàn thành",1,IF(N20="Done chờ Test",1,IF(N20="Đang làm",0.5,0)))+IF(O20="Hoàn thành",1,IF(O20="Done chờ Test",1,IF(O20="Đang làm",0.5,0)))+IF(P20="Hoàn thành",1,IF(P20="Done chờ Test",1,IF(P20="Đang làm",0.5,0))))/(4-COUNTIF(M20:P20,"N/A")),4),0) | R20: Đổi lịch đi qua cùng kiểm tra trùng lịch; hủy cần lý do; giới hạn thời gian đổi/hủy theo chính sách spa (cần xác nhận); hủy hợp lệ trả lại quyền sử dụng/buổi | S20: DA: 'kiểm tra và hủy khi được phép' — chưa định nghĩa điều kiện
A21: 17 | B21: UC-SPA-17 | C21: Đặt lịch & lịch hẹn | D21: BKG | E21: Quản lý lịch hẹn | F21: Chủ spa điều chỉnh lịch hẹn (xem, xác nhận, phân công nhân viên) và ghi nhận khách không đến | G21: OWN | H21: DA: có đặc tả | I21: P0 | J21: 7 | K21: Sprint 1 | L21: Web; Android (rút gọn) | M21: Chưa làm | N21: Chưa làm | O21: Chưa làm | P21: Chưa làm | Q21: =IFERROR(ROUND((IF(M21="Hoàn thành",1,IF(M21="Done chờ Test",1,IF(M21="Đang làm",0.5,0)))+IF(N21="Hoàn thành",1,IF(N21="Done chờ Test",1,IF(N21="Đang làm",0.5,0)))+IF(O21="Hoàn thành",1,IF(O21="Done chờ Test",1,IF(O21="Đang làm",0.5,0)))+IF(P21="Hoàn thành",1,IF(P21="Done chờ Test",1,IF(P21="Đang làm",0.5,0))))/(4-COUNTIF(M21:P21,"N/A")),4),0) | R21: Đổi giờ/đổi nhân viên kiểm tra trùng lịch và kỹ năng; hủy cần lý do; ghi nhận khách không đến chỉ sau giờ hẹn
A22: 18 | B22: UC-SPA-18 | C22: Quyền sử dụng & liệu trình | D22: TRT | E22: Xem dịch vụ và gói đã mua | F22: Khách xem sản phẩm đã mua và chọn chức năng liên quan | G22: CUS | H22: DA: có đặc tả | I22: P0 | J22: 3 | K22: Sprint 2 | L22: Web, Android | M22: Chưa làm | N22: Chưa làm | O22: Chưa làm | P22: Chưa làm | Q22: =IFERROR(ROUND((IF(M22="Hoàn thành",1,IF(M22="Done chờ Test",1,IF(M22="Đang làm",0.5,0)))+IF(N22="Hoàn thành",1,IF(N22="Done chờ Test",1,IF(N22="Đang làm",0.5,0)))+IF(O22="Hoàn thành",1,IF(O22="Done chờ Test",1,IF(O22="Đang làm",0.5,0)))+IF(P22="Hoàn thành",1,IF(P22="Done chờ Test",1,IF(P22="Đang làm",0.5,0))))/(4-COUNTIF(M22:P22,"N/A")),4),0) | R22: Hiển thị DichVuKhachHang và GoiKhachHang với hạn sử dụng, trạng thái, số buổi đã dùng/tổng; A1 đặt lịch bằng quyền đã mua; A2 xem liệu trình; A3 xem đơn nguồn
A23: 19 | B23: UC-SPA-19 | C23: Quyền sử dụng & liệu trình | D23: TRT | E23: Theo dõi liệu trình chăm sóc da | F23: Khách xem tiến độ và trạng thái các buổi chăm sóc | G23: CUS | H23: DA: có đặc tả | I23: P0 | J23: 4 | K23: Sprint 2 | L23: Web, Android | M23: Chưa làm | N23: Chưa làm | O23: Chưa làm | P23: Chưa làm | Q23: =IFERROR(ROUND((IF(M23="Hoàn thành",1,IF(M23="Done chờ Test",1,IF(M23="Đang làm",0.5,0)))+IF(N23="Hoàn thành",1,IF(N23="Done chờ Test",1,IF(N23="Đang làm",0.5,0)))+IF(O23="Hoàn thành",1,IF(O23="Done chờ Test",1,IF(O23="Đang làm",0.5,0)))+IF(P23="Hoàn thành",1,IF(P23="Done chờ Test",1,IF(P23="Đang làm",0.5,0))))/(4-COUNTIF(M23:P23,"N/A")),4),0) | R23: Hiển thị mục tiêu, tiến độ SoBuoiDaDung/TongSoBuoi, trạng thái từng BuoiChamSoc theo ThuTu; buổi đủ điều kiện mới cho đặt lịch
A24: 20 | B24: UC-SPA-20 | C24: Quyền sử dụng & liệu trình | D24: TRT | E24: Xem lịch sử sử dụng dịch vụ | F24: Khách xem các lần sử dụng dịch vụ trước đó | G24: CUS | H24: DA: có đặc tả | I24: P1 | J24: 2 | K24: Sprint 2 | L24: Web, Android | M24: Chưa làm | N24: Chưa làm | O24: Chưa làm | P24: Chưa làm | Q24: =IFERROR(ROUND((IF(M24="Hoàn thành",1,IF(M24="Done chờ Test",1,IF(M24="Đang làm",0.5,0)))+IF(N24="Hoàn thành",1,IF(N24="Done chờ Test",1,IF(N24="Đang làm",0.5,0)))+IF(O24="Hoàn thành",1,IF(O24="Done chờ Test",1,IF(O24="Đang làm",0.5,0)))+IF(P24="Hoàn thành",1,IF(P24="Done chờ Test",1,IF(P24="Đang làm",0.5,0))))/(4-COUNTIF(M24:P24,"N/A")),4),0) | R24: Danh sách lịch hẹn HoanThanh của khách; lọc theo thời gian/dịch vụ; chi tiết gồm nhân viên, ghi chú/kết quả buổi
A25: 21 | B25: UC-SPA-21 | C25: Quyền sử dụng & liệu trình | D25: TRT | E25: Quản lý liệu trình và lịch sử chăm sóc của khách hàng | F25: Chủ spa/nhân viên xem và cập nhật liệu trình (mục tiêu, nhân viên phụ trách, ngày dự kiến, ghi chú) và lịch sử chăm sóc từng khách | G25: OWN; STF | H25: DA: chỉ liệt kê, chưa đặc tả | I25: P0 | J25: 5 | K25: Sprint 2 | L25: Web; Android (nhân viên) | M25: Chưa làm | N25: Chưa làm | O25: Chưa làm | P25: Chưa làm | Q25: =IFERROR(ROUND((IF(M25="Hoàn thành",1,IF(M25="Done chờ Test",1,IF(M25="Đang làm",0.5,0)))+IF(N25="Hoàn thành",1,IF(N25="Done chờ Test",1,IF(N25="Đang làm",0.5,0)))+IF(O25="Hoàn thành",1,IF(O25="Done chờ Test",1,IF(O25="Đang làm",0.5,0)))+IF(P25="Hoàn thành",1,IF(P25="Done chờ Test",1,IF(P25="Đang làm",0.5,0))))/(4-COUNTIF(M25:P25,"N/A")),4),0) | R25: Lọc theo khách, trạng thái; nhân viên chỉ sửa liệu trình mình phụ trách; không sửa buổi đã hoàn thành | S25: Có ở cả Nhân viên và Chủ spa nhưng chưa có bảng đặc tả
A26: 22 | B26: UC-SPA-22 | C26: Nhân viên & lịch làm việc | D26: STF | E26: Quản lý nhân viên | F26: Chủ spa thêm hoặc sửa nhân viên và ghi nhận nghỉ việc | G26: OWN | H26: DA: có đặc tả | I26: P0 | J26: 4 | K26: Sprint 1 | L26: Web | M26: Chưa làm | N26: Chưa làm | O26: N/A | P26: Chưa làm | Q26: =IFERROR(ROUND((IF(M26="Hoàn thành",1,IF(M26="Done chờ Test",1,IF(M26="Đang làm",0.5,0)))+IF(N26="Hoàn thành",1,IF(N26="Done chờ Test",1,IF(N26="Đang làm",0.5,0)))+IF(O26="Hoàn thành",1,IF(O26="Done chờ Test",1,IF(O26="Đang làm",0.5,0)))+IF(P26="Hoàn thành",1,IF(P26="Done chờ Test",1,IF(P26="Đang làm",0.5,0))))/(4-COUNTIF(M26:P26,"N/A")),4),0) | R26: Tạo NguoiDung (VaiTro NhanVien) + NhanVien; chọn dịch vụ được thực hiện (NhanVien_DichVu); NgayNghiViec ≥ NgayVaoLam; nghỉ việc → không nhận lịch mới, lịch tương lai phải phân công lại
A27: 23 | B27: UC-SPA-23 | C27: Nhân viên & lịch làm việc | D27: STF | E27: Phân công lịch làm việc cho nhân viên | F27: Chủ spa thêm hoặc điều chỉnh ca làm | G27: OWN | H27: DA: có đặc tả | I27: P0 | J27: 6 | K27: Sprint 1 | L27: Web | M27: Chưa làm | N27: Chưa làm | O27: N/A | P27: Chưa làm | Q27: =IFERROR(ROUND((IF(M27="Hoàn thành",1,IF(M27="Done chờ Test",1,IF(M27="Đang làm",0.5,0)))+IF(N27="Hoàn thành",1,IF(N27="Done chờ Test",1,IF(N27="Đang làm",0.5,0)))+IF(O27="Hoàn thành",1,IF(O27="Done chờ Test",1,IF(O27="Đang làm",0.5,0)))+IF(P27="Hoàn thành",1,IF(P27="Done chờ Test",1,IF(P27="Đang làm",0.5,0))))/(4-COUNTIF(M27:P27,"N/A")),4),0) | R27: GioKetThuc > GioBatDau; không chồng ca cùng nhân viên; không sửa/xóa ca làm lịch hẹn đã đặt rơi ra ngoài ca (E1 xung đột)
A28: 24 | B28: UC-SPA-24 | C28: Nhân viên & lịch làm việc | D28: STF | E28: Xem lịch làm việc cá nhân | F28: Nhân viên xem các ca được phân công | G28: STF | H28: DA: có đặc tả | I28: P1 | J28: 2 | K28: Sprint 2 | L28: Web, Android | M28: Chưa làm | N28: Chưa làm | O28: Chưa làm | P28: Chưa làm | Q28: =IFERROR(ROUND((IF(M28="Hoàn thành",1,IF(M28="Done chờ Test",1,IF(M28="Đang làm",0.5,0)))+IF(N28="Hoàn thành",1,IF(N28="Done chờ Test",1,IF(N28="Đang làm",0.5,0)))+IF(O28="Hoàn thành",1,IF(O28="Done chờ Test",1,IF(O28="Đang làm",0.5,0)))+IF(P28="Hoàn thành",1,IF(P28="Done chờ Test",1,IF(P28="Đang làm",0.5,0))))/(4-COUNTIF(M28:P28,"N/A")),4),0) | R28: Chỉ ca của chính nhân viên; xem theo tuần/tháng
A29: 25 | B29: UC-SPA-25 | C29: Nhân viên & lịch làm việc | D29: STF | E29: Xem danh sách lịch hẹn được phân công | F29: Nhân viên xem lịch và thông tin dịch vụ được giao | G29: STF | H29: DA: có đặc tả | I29: P0 | J29: 3 | K29: Sprint 2 | L29: Web, Android | M29: Chưa làm | N29: Chưa làm | O29: Chưa làm | P29: Chưa làm | Q29: =IFERROR(ROUND((IF(M29="Hoàn thành",1,IF(M29="Done chờ Test",1,IF(M29="Đang làm",0.5,0)))+IF(N29="Hoàn thành",1,IF(N29="Done chờ Test",1,IF(N29="Đang làm",0.5,0)))+IF(O29="Hoàn thành",1,IF(O29="Done chờ Test",1,IF(O29="Đang làm",0.5,0)))+IF(P29="Hoàn thành",1,IF(P29="Done chờ Test",1,IF(P29="Đang làm",0.5,0))))/(4-COUNTIF(M29:P29,"N/A")),4),0) | R29: Lọc theo ngày/trạng thái; chi tiết có thông tin khách, dịch vụ, dị ứng; A1 chuyển lập hồ sơ da, A2 xác nhận hoàn thành
A30: 26 | B30: UC-SPA-26 | C30: Chăm sóc & hồ sơ da | D30: CARE | E30: Xem lịch sử các khách hàng đã chăm sóc | F30: Nhân viên xem các lần chăm sóc mình đã thực hiện | G30: STF | H30: DA: có đặc tả | I30: P1 | J30: 2 | K30: Sprint 2 | L30: Web, Android | M30: Chưa làm | N30: Chưa làm | O30: Chưa làm | P30: Chưa làm | Q30: =IFERROR(ROUND((IF(M30="Hoàn thành",1,IF(M30="Done chờ Test",1,IF(M30="Đang làm",0.5,0)))+IF(N30="Hoàn thành",1,IF(N30="Done chờ Test",1,IF(N30="Đang làm",0.5,0)))+IF(O30="Hoàn thành",1,IF(O30="Done chờ Test",1,IF(O30="Đang làm",0.5,0)))+IF(P30="Hoàn thành",1,IF(P30="Done chờ Test",1,IF(P30="Đang làm",0.5,0))))/(4-COUNTIF(M30:P30,"N/A")),4),0) | R30: Chỉ lịch hẹn do chính nhân viên thực hiện; tìm theo tên/SĐT khách, khoảng ngày | S30: Tên trong bảng đặc tả DA đang ghi nhầm 'Xem danh sách lịch hẹn được phân công'
A31: 27 | B31: UC-SPA-27 | C31: Chăm sóc & hồ sơ da | D31: CARE | E31: Lập và cập nhật hồ sơ da khách hàng | F31: Nhân viên tạo hoặc sửa hồ sơ của một lần chăm sóc | G31: STF | H31: DA: có đặc tả | I31: P0 | J31: 4 | K31: Sprint 2 | L31: Web, Android | M31: Chưa làm | N31: Chưa làm | O31: Chưa làm | P31: Chưa làm | Q31: =IFERROR(ROUND((IF(M31="Hoàn thành",1,IF(M31="Done chờ Test",1,IF(M31="Đang làm",0.5,0)))+IF(N31="Hoàn thành",1,IF(N31="Done chờ Test",1,IF(N31="Đang làm",0.5,0)))+IF(O31="Hoàn thành",1,IF(O31="Done chờ Test",1,IF(O31="Đang làm",0.5,0)))+IF(P31="Hoàn thành",1,IF(P31="Done chờ Test",1,IF(P31="Đang làm",0.5,0))))/(4-COUNTIF(M31:P31,"N/A")),4),0) | R31: Mỗi lịch hẹn tối đa 1 HoSoDa (IdLichHen unique); LoaiDa bắt buộc; hiển thị và cập nhật DiUngKhachHang; chỉ nhân viên của lịch hẹn
A32: 28 | B32: UC-SPA-28 | C32: Chăm sóc & hồ sơ da | D32: CARE | E32: Xác nhận hoàn thành buổi chăm sóc | F32: Nhân viên ghi nhận lịch đã hoàn thành và cập nhật lượt sử dụng | G32: STF | H32: DA: có đặc tả | I32: P0 | J32: 6 | K32: Sprint 2 | L32: Web, Android | M32: Chưa làm | N32: Chưa làm | O32: Chưa làm | P32: Chưa làm | Q32: =IFERROR(ROUND((IF(M32="Hoàn thành",1,IF(M32="Done chờ Test",1,IF(M32="Đang làm",0.5,0)))+IF(N32="Hoàn thành",1,IF(N32="Done chờ Test",1,IF(N32="Đang làm",0.5,0)))+IF(O32="Hoàn thành",1,IF(O32="Done chờ Test",1,IF(O32="Đang làm",0.5,0)))+IF(P32="Hoàn thành",1,IF(P32="Done chờ Test",1,IF(P32="Đang làm",0.5,0))))/(4-COUNTIF(M32:P32,"N/A")),4),0) | R32: Chỉ nhân viên được phân công, lịch DaXacNhan, không trước giờ bắt đầu; dịch vụ lẻ → DichVuKhachHang DaSuDung; buổi trong gói → BuoiChamSoc HoanThanh, SoBuoiDaDung + 1, đủ buổi thì gói và liệu trình HoanThanh; thực hiện trong 1 giao dịch
A33: 29 | B33: UC-SPA-29 | C33: Đánh giá | D33: REV | E33: Xem đánh giá dịch vụ | F33: Người dùng xem đánh giá về dịch vụ hoặc gói | G33: GUEST; CUS | H33: DA: có đặc tả | I33: P1 | J33: 2 | K33: Sprint 1 | L33: Web, Android | M33: Chưa làm | N33: Chưa làm | O33: Chưa làm | P33: Chưa làm | Q33: =IFERROR(ROUND((IF(M33="Hoàn thành",1,IF(M33="Done chờ Test",1,IF(M33="Đang làm",0.5,0)))+IF(N33="Hoàn thành",1,IF(N33="Done chờ Test",1,IF(N33="Đang làm",0.5,0)))+IF(O33="Hoàn thành",1,IF(O33="Done chờ Test",1,IF(O33="Đang làm",0.5,0)))+IF(P33="Hoàn thành",1,IF(P33="Done chờ Test",1,IF(P33="Đang làm",0.5,0))))/(4-COUNTIF(M33:P33,"N/A")),4),0) | R33: Chỉ đánh giá TrangThai = HienThi; điểm trung bình + số lượng; lọc theo số sao; hiển thị phản hồi của spa
A34: 30 | B34: UC-SPA-30 | C34: Đánh giá | D34: REV | E34: Đánh giá dịch vụ | F34: Khách đánh giá dịch vụ hoặc gói đã đủ điều kiện | G34: CUS | H34: DA: có đặc tả | I34: P1 | J34: 4 | K34: Sprint 2 | L34: Web, Android | M34: Chưa làm | N34: Chưa làm | O34: Chưa làm | P34: Chưa làm | Q34: =IFERROR(ROUND((IF(M34="Hoàn thành",1,IF(M34="Done chờ Test",1,IF(M34="Đang làm",0.5,0)))+IF(N34="Hoàn thành",1,IF(N34="Done chờ Test",1,IF(N34="Đang làm",0.5,0)))+IF(O34="Hoàn thành",1,IF(O34="Done chờ Test",1,IF(O34="Đang làm",0.5,0)))+IF(P34="Hoàn thành",1,IF(P34="Done chờ Test",1,IF(P34="Đang làm",0.5,0))))/(4-COUNTIF(M34:P34,"N/A")),4),0) | R34: Đủ điều kiện: đã sử dụng dịch vụ hoặc hoàn thành đủ số buổi theo quy định (cần chốt số buổi); SoSao 1–5; ảnh tùy chọn; mỗi khách 1 đánh giá/dịch vụ hoặc gói (đề xuất) | S34: 'Đủ số buổi theo quy định' chưa được định nghĩa
A35: 31 | B35: UC-SPA-31 | C35: Đánh giá | D35: REV | E35: Quản lý đánh giá dịch vụ | F35: Chủ spa phản hồi hoặc ẩn đánh giá | G35: OWN | H35: DA: có đặc tả | I35: P2 | J35: 2 | K35: Sprint 3 | L35: Web | M35: Chưa làm | N35: Chưa làm | O35: N/A | P35: Chưa làm | Q35: =IFERROR(ROUND((IF(M35="Hoàn thành",1,IF(M35="Done chờ Test",1,IF(M35="Đang làm",0.5,0)))+IF(N35="Hoàn thành",1,IF(N35="Done chờ Test",1,IF(N35="Đang làm",0.5,0)))+IF(O35="Hoàn thành",1,IF(O35="Done chờ Test",1,IF(O35="Đang làm",0.5,0)))+IF(P35="Hoàn thành",1,IF(P35="Done chờ Test",1,IF(P35="Đang làm",0.5,0))))/(4-COUNTIF(M35:P35,"N/A")),4),0) | R35: Phản hồi lưu PhanHoiTuSpa + PhanHoiLuc; ẩn đổi TrangThai, không xóa
A36: 32 | B36: UC-SPA-32 | C36: Trợ lý AI | D36: AI | E36: Trò chuyện với trợ lý AI tư vấn dịch vụ | F36: Khách hàng trao đổi với AI để được tư vấn về dịch vụ | G36: GUEST; CUS; LLM | H36: DA: có đặc tả | I36: P1 | J36: 8 | K36: Sprint 3 | L36: Web, Android | M36: Chưa làm | N36: Chưa làm | O36: Chưa làm | P36: Chưa làm | Q36: =IFERROR(ROUND((IF(M36="Hoàn thành",1,IF(M36="Done chờ Test",1,IF(M36="Đang làm",0.5,0)))+IF(N36="Hoàn thành",1,IF(N36="Done chờ Test",1,IF(N36="Đang làm",0.5,0)))+IF(O36="Hoàn thành",1,IF(O36="Done chờ Test",1,IF(O36="Đang làm",0.5,0)))+IF(P36="Hoàn thành",1,IF(P36="Done chờ Test",1,IF(P36="Đang làm",0.5,0))))/(4-COUNTIF(M36:P36,"N/A")),4),0) | R36: Kiểm tra nội dung trước khi gửi; AI chỉ dựa trên dịch vụ/gói đang bán và dữ liệu của chính khách (lịch hẹn, số buổi còn lại); không chẩn đoán y khoa; lưu câu hỏi + câu trả lời; E2 lỗi phản hồi cho gửi lại | S36: DA: actor gồm Khách vãng lai nhưng LichSuTroChuyenAI.IdKhachHang not null — cần chốt
A37: 33 | B37: UC-SPA-33 | C37: Thống kê & báo cáo | D37: RPT | E37: Xem thống kê báo cáo doanh thu | F37: Chủ spa xem số liệu theo khoảng thời gian và tiêu chí | G37: OWN | H37: DA: có đặc tả | I37: P0 | J37: 5 | K37: Sprint 3 | L37: Web; Android (xem) | M37: Chưa làm | N37: Chưa làm | O37: Chưa làm | P37: Chưa làm | Q37: =IFERROR(ROUND((IF(M37="Hoàn thành",1,IF(M37="Done chờ Test",1,IF(M37="Đang làm",0.5,0)))+IF(N37="Hoàn thành",1,IF(N37="Done chờ Test",1,IF(N37="Đang làm",0.5,0)))+IF(O37="Hoàn thành",1,IF(O37="Done chờ Test",1,IF(O37="Đang làm",0.5,0)))+IF(P37="Hoàn thành",1,IF(P37="Done chờ Test",1,IF(P37="Đang làm",0.5,0))))/(4-COUNTIF(M37:P37,"N/A")),4),0) | R37: Theo tháng, quý, năm (MT-5); doanh thu từ ThanhToan thành công; tiêu chí: dịch vụ lẻ/gói, sản phẩm; biểu đồ + bảng số liệu
A38: 34 | B38: UC-SPA-34 | C38: Thông báo | D38: NTF | E38: Xem thông báo | F38: Người dùng xem thông báo được gửi đến mình | G38: CUS; STF | H38: DA: có đặc tả | I38: P2 | J38: 2 | K38: Sprint 3 | L38: Web, Android | M38: Chưa làm | N38: Chưa làm | O38: Chưa làm | P38: Chưa làm | Q38: =IFERROR(ROUND((IF(M38="Hoàn thành",1,IF(M38="Done chờ Test",1,IF(M38="Đang làm",0.5,0)))+IF(N38="Hoàn thành",1,IF(N38="Done chờ Test",1,IF(N38="Đang làm",0.5,0)))+IF(O38="Hoàn thành",1,IF(O38="Done chờ Test",1,IF(O38="Đang làm",0.5,0)))+IF(P38="Hoàn thành",1,IF(P38="Done chờ Test",1,IF(P38="Đang làm",0.5,0))))/(4-COUNTIF(M38:P38,"N/A")),4),0) | R38: Chỉ thông báo của chính người dùng; mở thông báo thì ghi DocLuc; hiển thị số chưa đọc

Sheet 05_Dac_ta_UC
A1: 05 · ĐẶC TẢ USE CASE
A2: 34 đặc tả · cùng thứ tự và mã với 04_Checklist_UC
A3: Cột Input → Exception flow trích nguyên ý từ bảng kịch bản trong DA (đã sửa tên UC bị ghi nhầm). Cột 'Rà soát / bổ sung' là nhận xét và đề xuất, không có trong DA.
A4: STT | B4: Mã UC | C4: Tên Use Case | D4: Description | E4: Actors | F4: Đặc tả | G4: Input | H4: Output | I4: Basic flow | J4: Alternative flow | K4: Exception flow | L4: Rà soát / bổ sung (ĐX) | M4: Business rules
A5: 1 | B5: ='04_Checklist_UC'!B5 | C5: ='04_Checklist_UC'!E5 | D5: ='04_Checklist_UC'!F5 | E5: ='04_Checklist_UC'!G5 | F5: Có trong DA | G5: Họ tên; Email; Số điện thoại; Mật khẩu; Xác nhận mật khẩu; OTP | H5: Đăng ký thành công hoặc thông báo lỗi | I5: 1. Khách mở trang đăng ký 2. Hệ thống hiển thị biểu mẫu 3. Khách nhập thông tin và nhấn đăng ký 4. Hệ thống kiểm tra dữ liệu 5. Hệ thống gửi OTP xác nhận email 6. Khách nhập OTP và xác nhận 7. Hệ thống kiểm tra OTP 8. Nếu hợp lệ → Hoàn tất tạo tài khoản và chuyển đến đăng nhập | J5: — | K5: E1. Thông tin đăng ký không hợp lệ → Hiển thị lỗi và không hoàn tất đăng ký E2. OTP không hợp lệ → Thông báo lỗi và chuyển về trang đăng ký | L5: ĐX: thêm A1 'Gửi lại OTP' (giới hạn 60 giây/lần); E3 OTP hết hạn; E4 email/SĐT đã tồn tại | M5: BR-AUTH-01, 02
A6: 2 | B6: ='04_Checklist_UC'!B6 | C6: ='04_Checklist_UC'!E6 | D6: ='04_Checklist_UC'!F6 | E6: ='04_Checklist_UC'!G6 | F6: Có trong DA | G6: Thông tin đăng nhập và mật khẩu | H6: Đăng nhập thành công hoặc thông báo lỗi | I6: 1. Người dùng mở trang đăng nhập 2. Hệ thống hiển thị biểu mẫu 3. Người dùng nhập thông tin và mật khẩu 4. Hệ thống kiểm tra thông tin 5. Hệ thống kiểm tra trạng thái tài khoản 6. Nếu được hoạt động → Đăng nhập và chuyển đến trang phù hợp với vai trò | J6: A1. Người dùng đăng nhập từ thao tác đang dở → Quay lại thao tác trước đăng nhập | K6: E1. Thông tin không chính xác → Thông báo lỗi và quay lại nhập E2. Tài khoản bị khóa hoặc ngừng hoạt động → Thông báo và kết thúc | L6: ĐX: không tiết lộ email có tồn tại hay không; khóa tạm sau nhiều lần sai | M6: BR-AUTH-03
A7: 3 | B7: ='04_Checklist_UC'!B7 | C7: ='04_Checklist_UC'!E7 | D7: ='04_Checklist_UC'!F7 | E7: ='04_Checklist_UC'!G7 | F7: Có trong DA | G7: Email; OTP; Mật khẩu mới; Xác nhận mật khẩu | H7: Mật khẩu được cập nhật hoặc thông báo lỗi | I7: 1. Người dùng chọn quên mật khẩu 2. Hệ thống hiển thị biểu mẫu email 3. Người dùng nhập email và gửi yêu cầu 4. Hệ thống kiểm tra email rồi gửi OTP 5. Người dùng nhập OTP và xác nhận 6. Hệ thống kiểm tra OTP và hiển thị biểu mẫu mật khẩu mới 7. Người dùng nhập và xác nhận mật khẩu mới 8. Hệ thống cập nhật tài khoản và thông báo thành công | J7: — | K7: E1. Email không hợp lệ hoặc không tồn tại → Thông báo và kết thúc E2. OTP không hợp lệ → Thông báo và kết thúc | L7: Rà soát: ô ngoại lệ trong DA có chữ thừa 'flow' và ghi chú nháp 'Sơ đồ chưa thể hiện nhánh mật khẩu mới không hợp lệ' → bổ sung E3: mật khẩu mới không hợp lệ/không khớp → báo lỗi, nhập lại | M7: BR-AUTH-01, 02
A8: 4 | B8: ='04_Checklist_UC'!B8 | C8: ='04_Checklist_UC'!E8 | D8: ='04_Checklist_UC'!F8 | E8: ='04_Checklist_UC'!G8 | F8: Có trong DA | G8: Thông tin tài khoản cần cập nhật | H8: Thông tin được lưu hoặc thông báo lỗi | I8: 1. Người dùng mở thông tin tài khoản 2. Hệ thống hiển thị thông tin hiện tại 3. Người dùng chỉnh sửa và chọn lưu 4. Hệ thống kiểm tra dữ liệu 5. Hệ thống cập nhật và thông báo thành công | J8: — | K8: E1. Dữ liệu không hợp lệ → Hiển thị lỗi và quay lại bước chỉnh sửa | L8: Rà soát: hàng 'Usecase name' trong DA ghi nhầm 'Quản lý đơn hàng đã mua'. ĐX: thêm A1 đổi mật khẩu, A2 đổi ảnh đại diện | M8: BR-AUTH-04
A9: 5 | B9: ='04_Checklist_UC'!B9 | C9: ='04_Checklist_UC'!E9 | D9: ='04_Checklist_UC'!F9 | E9: ='04_Checklist_UC'!G9 | F9: Có trong DA | G9: Tài khoản được chọn; Thông tin thay đổi; Thao tác | H9: Chi tiết tài khoản hoặc kết quả cập nhật | I9: 1. Chủ spa mở danh sách tài khoản 2. Hệ thống hiển thị danh sách 3. Chủ spa tìm và chọn tài khoản 4. Chủ spa chọn xem thông tin 5. Hệ thống hiển thị chi tiết | J9: A1. Chủ spa chọn sửa → Hệ thống mở biểu mẫu → Chủ spa nhập và lưu → Hệ thống kiểm tra rồi cập nhật A2. Chủ spa chọn khóa hoặc mở khóa và xác nhận → Hệ thống cập nhật trạng thái và thông báo | K9: E1. Dữ liệu chỉnh sửa không hợp lệ → Thông báo lỗi cụ thể và kết thúc thao tác | L9: ĐX: khóa tài khoản → thu hồi refresh token; không cho chủ spa tự khóa mình | M9: BR-AUTH-05
A10: 6 | B10: ='04_Checklist_UC'!B10 | C10: ='04_Checklist_UC'!E10 | D10: ='04_Checklist_UC'!F10 | E10: ='04_Checklist_UC'!G10 | F10: Có trong DA | G10: Từ khóa (tùy chọn), Danh mục (tùy chọn) | H10: Danh sách dịch vụ/gói dịch vụ phù hợp được hiển thị theo phân trang | I10: 1. Actor mở trang dịch vụ 2. Hệ thống tải danh sách DichVu và GoiDichVu, chỉ hiển thị các mục đang ở trạng thái 'DangBan' 3. Nếu actor là khách hàng đã đăng nhập, hệ thống kiểm tra các liệu trình đang có của khách hàng để đánh dấu những dịch vụ/gói đã từng sử dụng 4. Actor nhập từ khóa và chọn danh mục dịch vụ để lọc 5. Actor nhấn nút 'Tìm kiếm' hoặc hệ thống tự động lọc 6. Hệ thống lọc DichVu/GoiDichVu theo từ khóa và danh mục đã chọn 7. Nếu actor bật 'Chỉ hiện dịch vụ đã từng sử dụng', hệ thống lọc thêm theo lịch sử sử dụng của khách hàng 8. Hệ thống hiển thị danh sách dịch vụ và gói dịch vụ theo phân trang 9. Actor chọn một dịch vụ hoặc gói dịch vụ để mở chi tiết 10. Use case kết thúc | J10: A1. Actor chọn gợi ý tìm kiếm → Hệ thống mở dịch vụ hoặc gói dịch vụ theo gợi ý A2. Actor chọn xóa bộ lọc → Hệ thống đặt lại từ khóa, danh mục dịch vụ và khoảng giá A3. Actor hỏi trợ lý AI → Hệ thống gửi câu hỏi tới trợ lý AI và hiển thị câu trả lời gợi ý dịch vụ phù hợp với nhu cầu | K10: E1. Không có dịch vụ phù hợp → Hệ thống hiển thị trạng thái không có kết quả và gợi ý đổi từ khóa hoặc danh mục E2. Actor chọn lưu dịch vụ nhưng chưa đăng nhập → Hệ thống chuyển hướng sang trang đăng nhập | L10: Rà soát: Input thiếu 'khoảng giá' (A2 có nhắc); E2 'lưu dịch vụ' không có UC/bảng tương ứng (có thể là Thêm vào giỏ) — cần thống nhất. 'Danh mục' = DichVu.LoaiDichVu; GoiDichVu không có danh mục | M10: BR-CAT-01
A11: 7 | B11: ='04_Checklist_UC'!B11 | C11: ='04_Checklist_UC'!E11 | D11: ='04_Checklist_UC'!F11 | E11: ='04_Checklist_UC'!G11 | F11: ĐX (DA chưa có bảng) | G11: Dịch vụ hoặc gói được chọn | H11: Thông tin chi tiết | I11: 1. Actor chọn một dịch vụ hoặc gói 2. Hệ thống tải thông tin (chỉ mục DangBan) 3. Hệ thống hiển thị mô tả, giá, thời lượng, hình ảnh; với gói: các dịch vụ thành phần, số buổi, thứ tự, thời hạn 4. Hệ thống hiển thị điểm đánh giá trung bình (liên kết UC-SPA-29) 5. Actor chọn Thêm vào giỏ, Đặt ngay hoặc quay lại | J11: A1. Chưa đăng nhập mà chọn Thêm vào giỏ/Đặt ngay → chuyển đăng nhập rồi quay lại (UC-SPA-02 A1) | K11: E1. Sản phẩm không tồn tại hoặc ngừng bán → thông báo và quay về danh sách | L11: Toàn bộ đặc tả là ĐỀ XUẤT vì DA chưa có bảng kịch bản | M11: BR-CAT-01
A12: 8 | B12: ='04_Checklist_UC'!B12 | C12: ='04_Checklist_UC'!E12 | D12: ='04_Checklist_UC'!F12 | E12: ='04_Checklist_UC'!G12 | F12: Có trong DA | G12: Yêu cầu mở trang giới thiệu | H12: Thông tin giới thiệu về spa | I12: 1. Người dùng mở trang giới thiệu 2. Hệ thống tải và hiển thị thông tin spa 3. Người dùng xem nội dung 4. Người dùng quay lại hoặc rời trang | J12: (DA đang chép A1–A3 của UC Tìm kiếm — đề nghị xóa) | K12: (DA đang chép E1–E2 của UC Tìm kiếm — đề nghị xóa) | L12: Rà soát: luồng rẽ nhánh/ngoại lệ không thuộc UC này. ERD không có bảng lưu thông tin spa → dùng cấu hình (appsettings) hoặc bổ sung bảng ThongTinSpa | M12: —
A13: 9 | B13: ='04_Checklist_UC'!B13 | C13: ='04_Checklist_UC'!E13 | D13: ='04_Checklist_UC'!F13 | E13: ='04_Checklist_UC'!G13 | F13: Có trong DA | G13: Loại sản phẩm; Thông tin dịch vụ hoặc gói; Các dịch vụ thành phần và số buổi | H13: Sản phẩm được lưu hoặc cập nhật trạng thái | I13: 1. Chủ spa mở danh sách dịch vụ và gói 2. Hệ thống hiển thị danh sách 3. Chủ spa chọn thêm mới 4. Hệ thống hiển thị biểu mẫu 5. Chủ spa chọn loại sản phẩm và nhập thông tin 6. Với gói → Nhập thông tin gói và các dịch vụ thành phần cùng số buổi 7. Hệ thống kiểm tra rồi lưu và thông báo | J13: A1. Chủ spa chọn sửa → Hệ thống mở biểu mẫu chỉnh sửa → Chủ spa nhập và lưu → Hệ thống kiểm tra rồi cập nhật A2. Chủ spa chọn ngừng bán và xác nhận → Hệ thống cập nhật trạng thái | K13: E1. Dữ liệu không hợp lệ → Hiển thị chi tiết lỗi và kết thúc thao tác | L13: ĐX: với gói nhập thêm ThuTu và KhoangCachNgayToiThieu từng dịch vụ thành phần; NgayBatDauBan/NgayKetThucBan | M13: BR-CAT-01, 02, 03
A14: 10 | B14: ='04_Checklist_UC'!B14 | C14: ='04_Checklist_UC'!E14 | D14: ='04_Checklist_UC'!F14 | E14: ='04_Checklist_UC'!G14 | F14: Có trong DA | G14: Dịch vụ hoặc gói được chọn; Thao tác với giỏ | H14: Giỏ hàng được cập nhật hoặc mở trang thanh toán | I14: 1. Khách mở danh sách dịch vụ và gói 2. Hệ thống tải danh sách 3. Khách nhấn thêm vào giỏ tại sản phẩm 4. Hệ thống kiểm tra sản phẩm đã có trong giỏ chưa 5. Nếu chưa có → Hệ thống tạo chi tiết giỏ hàng và ghi nhận giá | J14: A1. Khách mở giỏ → Hệ thống hiển thị chi tiết giỏ A2. Khách xóa sản phẩm và xác nhận → Hệ thống xóa rồi cập nhật tổng tiền A3. Khách chọn thanh toán → Hệ thống chuyển đến trang thanh toán | K14: E1. Sản phẩm đã tồn tại trong giỏ → Thông báo và không thêm trùng | L14: ĐX: nếu sản phẩm trong giỏ đã ngừng bán/đổi giá → đánh dấu khi mở giỏ | M14: BR-ORD-01
A15: 11 | B15: ='04_Checklist_UC'!B15 | C15: ='04_Checklist_UC'!E15 | D15: ='04_Checklist_UC'!F15 | E15: ='04_Checklist_UC'!G15 | F15: Có trong DA | G15: Sản phẩm cần mua; Mã khuyến mãi nếu có; Kết quả giao dịch | H15: Trạng thái thanh toán và đơn hàng; Quyền sử dụng khi thành công | I15: 1. Khách chọn thanh toán từ giỏ hoặc luồng đặt ngay 2. Hệ thống kiểm tra sản phẩm còn bán và lấy giá hiện tại 3. Hệ thống hiển thị thông tin đơn 4. Khách xác nhận thanh toán 5. Hệ thống tạo hoặc sử dụng đơn giữ chỗ đã có và chuyển đến cổng 6. Khách thực hiện thanh toán 7. Cổng xử lý và gửi kết quả 8. Hệ thống kiểm tra kết quả hợp lệ rồi cập nhật thanh toán và đơn hàng 9. Hệ thống tạo quyền sử dụng | J15: A1. Khách nhập mã khuyến mãi hợp lệ → Hệ thống tính số tiền giảm và tổng thanh toán A2. Thanh toán thất bại và khách muốn thử lại → Tạo lần thử thanh toán mới trên đơn đủ điều kiện A3. Khách không thử lại → Kết thúc | K15: E1. Mã không hợp lệ → Thông báo lỗi để khách sửa hoặc bỏ mã E2. Thanh toán không thành công hoặc kết quả không hợp lệ → Thông báo chưa ghi nhận thành công | L15: ĐX: bước 8 xử lý idempotent (cổng có thể gọi nhiều lần); bước 9 tạo DichVuKhachHang cho mỗi dịch vụ lẻ, GoiKhachHang + LieuTrinh + BuoiChamSoc cho mỗi gói; xóa sản phẩm đã mua khỏi giỏ | M15: BR-ORD-02..06; BR-PRM-01..03
